Workbook

Sheet Loan_Book
B2: Master Loan Book
B4: Loan_ID | C4: Source | D4: Obligor_Name | E4: Industry | F4: Tranche | G4: Commitment_USD | H4: Current_Balance_USD | I4: Coupon_Type | J4: Rate | K4: Payment_Freq | L4: Last_Payment_Date | M4: Days_Delinquent | N4: Status | O4: Cash_Interest_Q4 | P4: Accrued_PIK_Q4 | Q4: Notes / Adjustment
B6: WTM-L-0001 | C6: Alpha | D6: Orion Studios Holdings LLC | E6: Film Production | F6: Term A | G6: 45000000 | H6: 45000000 | I6: Floating | J6: SOFR+650 | K6: Quarterly | L6: 46022 | M6: 0 | N6: Performing | O6: 1148625 | P6: 0 | Q6: Bilateral
B7: WTM-L-0004 | C7: Alpha | D7: Prismrock Live Events Inc | E7: Live Entertainment | F7: Term Loan | G7: 20000000 | H7: 20000000 | I7: Fixed | J7: 0.095 | K7: Quarterly | L7: 46022 | M7: 0 | N7: Performing | O7: 475000 | P7: 0
B8: WTM-L-0005 | C8: Alpha | D8: Lumivue Streaming Corp | E8: Streaming | F8: Unitranche | G8: 80000000 | H8: 80000000 | I8: Floating | J8: SOFR+700 | K8: Quarterly | L8: 46022 | M8: 0 | N8: Performing | O8: 2172000 | P8: 0
B9: WTM-L-0007 | C9: Alpha | D9: Ridgeline Post-Production LLC | E9: Post Production | F9: Term Loan | G9: 15000000 | H9: 15000000 | I9: Fixed | J9: 0.11 | K9: Quarterly | L9: 46022 | M9: 0 | N9: Performing | O9: 412500 | P9: 0
B10: WTM-L-0008 | C10: Alpha | D10: Frostgate Films Ltd | E10: Film Production | F10: Term Loan | G10: 22000000 | H10: 22000000 | I10: Floating | J10: SOFR+600 | K10: Quarterly | L10: 46022 | M10: 0 | N10: Performing | O10: 529100 | P10: 0 | Q10: GBP-denominated obligor; loan USD
B11: WTM-L-0012 | C11: Alpha | D11: Greystone Bridge Loan | E11: Bridge | F11: Bridge | G11: 12000000 | H11: 12000000 | I11: Floating | J11: SOFR+800 | K11: Monthly | L11: 46022 | M11: 0 | N11: Performing | O11: 127000 | P11: 0 | Q11: Short-dated bridge
B12: WTM-L-0011/ BLA-0044 | C12: Both | D12: Timberline Music Rights I LLC | E12: Music Publishing | F12: Term Loan | G12: 35000000 | H12: 30500000 | I12: Fixed | J12: 0.09 | K12: Quarterly | L12: 46022 | M12: 0 | N12: Performing | O12: 687500 | P12: 0 | Q12: Corrected for $4.5M prepayment on 05-Oct-2025 per Notice 3. Alpha tape showed $35M (incorrect).
B13: WTM-L-0002 | C13: Both | D13: Orion Studios Holdings LLC | E13: Film Production | F13: Mezzanine | G13: 25000000 | H13: 11875000 | I13: Fixed | J13: 0.1025 | K13: Quarterly | L13: 45930 | M13: 92 | N13: Restructured | O13: 0 | P13: 0 | Q13: Exchanged under RSA dated 15-Aug-2025 for new Senior Secured Notes of $11.875M. Accrued interest on missed Dec-25 payment reversed. Original balance $25M written down.
B14: WTM-L-0003 | C14: Alpha | D14: Emberlight Records Group | E14: Music Publishing | F14: Senior Secured | G14: 60000000 | H14: 58500000 | I14: Floating | J14: SOFR + 525 | K14: Monthly | L14: 46022 | M14: 0 | N14: Performing | O14: 464625 | P14: 0 | Q14: Main loan. PIK toggle exists separately.
B15: WTM-L-0013-PIK | C15: Alpha | D15: Emberlight Records Group | E15: Music Publishing | F15: PIK Toggle | G15: 1850000 | H15: 1850000 | I15: Fixed | J15: 0.125 | K15: PIK | L15: 46022 | M15: 0 | N15: PIK | O15: 0 | P15: 781250 | Q15: Cumulative PIK $1.85M through Dec-25. December election $781,250 added to principal. Recognized as accrued income (not cash).
B16: WTM-L-0006 | C16: Both | D16: Solara Content Partners | E16: Content Rights | F16: Revolver | G16: 50000000 | H16: 32000000 | I16: Floating | J16: SOFR + 475 | K16: Quarterly | L16: 46022 | M16: 0 | N16: Performing | O16: 656000 | P16: 0 | Q16: Drawn balance taken from Revolver Utilization Report. Commitment $50M, Drawn $32M. Unused fee 50bps.
B17: BLA-0128 | C17: Beta | D17: Orion Studios Holdings LLC | E17: Film Production | F17: Revolver | G17: 15000000 | H17: 9750000 | I17: Floating | J17: SOFR + 525 | K17: Quarterly | L17: 46022 | M17: 0 | N17: Performing | O17: 189150 | P17: 0 | Q17: Orion Revolver (separate from Term A). Drawn $9.75M. Drawdown frozen post restructuring (Notice).
B18: WTM-L-0009 | C18: Both | D18: Haruki Anime Studios KK | E18: Film Production | F18: Term Loan | G18: 18000000 | H18: 18000000 | I18: Fixed | J18: 0.0875 | K18: Semi-Annual | L18: 46022 | M18: 0 | N18: Performing | O18: 787500 | P18: 0 | Q18: USD-linked loan with JPY revenue. FX forward is under-hedged after Nov-2025 notional reset (see Notice 4).
B19: BLA-0088 | C19: Beta | D19: Thornbury Publishing GBP LTD | E19: Music Publishing | F19: Senior Secured | G19: 28000000 | H19: 28000000 | I19: Fixed | J19: 0.0675 | K19: Quarterly | L19: 46022 | M19: 0 | N19: Performing | O19: 472500 | P19: 0 | Q19: GBP-denominated loan. FX-hedged via forward.
B20: BLA-0119 | C20: Beta | D20: Equinox Live Ent GmbH | E20: Live Entertainment | F20: Term Loan | G20: 18000000 | H20: 18000000 | I20: Fixed | J20: 0.075 | K20: Quarterly | L20: 46022 | M20: 0 | N20: Performing | O20: 337500 | P20: 0 | Q20: EUR-denominated loan.
B21: BLA-0141 | C21: Beta | D21: Dawnridge Post-Prod Services | E21: Post Production | F21: Term Loan | G21: 14000000 | H21: 14000000 | I21: Fixed | J21: 0.1025 | K21: Quarterly | L21: 46022 | M21: 0 | N21: Performing | O21: 358750 | P21: 0 | Q21: Moved from Beta to Alpha on 01-Dec-2025. Actual origination date 20-Apr-2025.
B22: BLA-0171 | C22: Beta | D22: Lumivue Streaming Corp | E22: Streaming | F22: Second Lien | G22: 40000000 | H22: 40000000 | I22: Fixed | J22: 0.115 | K22: Quarterly | L22: 46022 | M22: 0 | N22: Performing | O22: 1150000 | P22: 0 | Q22: Separate from Alpha Unitranche (WTM-L-0005).

Sheet Loan_Book_Summary
B2: Summary Calculation
B3: Whitmore Fund II Loan Book As of 31 December 2025
B5: Total Funded Balance | D5: =SUM(Loan_Book!H6:H22) -> 456475000
B7: Cash Interest Received in Q4 | D7: =SUM(Loan_Book!O6:O22) -> 9967750
B9: Accrued PIK Interest (Q4) | D9: =Loan_Book!P15 -> 781250
B11: Cumulative PIK (as of 31-Dec) | D11: =Loan_Book!G15 -> 1850000
B13: Impact of Orion Restructuring
B14: Original Mezzanine Exposure | D14: =Loan_Book!G13 -> 25000000
B15: New Carrying Value (47.5%) | D15: =D14*0.475 -> 11875000
B16: Write-down / Loss | D16: =D14-D15 -> 13125000
B17: Coupon change on Senior Loan | D17: From SOFR+650 → SOFR+525

Sheet Derivatives_CDS
B2: Item | C2: Value | D2: Source / Notes
B3: Reference Entity | C3: Orion Studios Holdings LLC | D3: CDS Confirmation
B4: Notional | C4: 25000000 | D4: CDS Confirmation
B5: Fund Role | C5: Buyer of Protection (Fixed Rate Payer) | D5: Main Confirmation text
B6: Annual Premium | C6: 100 bps | D6: Paid by Fund
B7: Upfront Payment Received | C7: 1687500 | D7: Received 24-Apr-2024 (to be amortised)
B8: Credit Event | C8: Restructuring (10-Sep-2025) | D8: ISDA Determinations Committee
B9: Auction Final Price | C9: 42.25 | D9: 24-Sep-2025 auction
B10: Settlement Amount Received | C10: 14437500 | D10: (100-42.25) × 25m
B11: Settlement Date | C11: 45928 | D11: Auction settlement
B12: Direction Assumption | C12: Fund receives the settlement | D12: Based on main Confirmation (priority over ops note)

Sheet Derivatives_FX_Forwards
B2: Trade_ID | C2: Currency_Pair | D2: Purpose | E2: Notional | F2: Direction | G2: Contract_Rate | H2: Value_Date | I2: Status | J2: Realised_PnL_USD | K2: Notes
B3: WTM-FX-0044 | C3: GBP/USD | D3: Hedge Thornbury loan (BLA-0088) | E3: GBP 22,400,000 | F3: Buy GBP / Sell USD | G3: 1.36 | H3: 46022 | I3: Settled | J3: -2273600 | K3: Large loss due to GBP depreciation. Rolled at off-market rate as part of package.
B4: WTM-FX-0045 | C4: USD/JPY | D4: Hedge Haruki Anime loan | E4: JPY 2,400,000,000 | F4: Sell JPY / Buy USD | G4: 152 | H4: 46022 | I4: Settled | J4: -493860 | K4: Under-hedged after Nov-2025 loan notional reset. Loss on settlement.
B5: WTM-FX-0046 | C5: EUR/USD | D5: Unclear / new trade | E5: EUR 4,750,000 | F5: Buy EUR / Sell USD | G5: 1.085 | H5: 46112 | I5: Open | J5: 0 | K5: Purpose not confirmed. Outside normal loan-hedging program.
B7: RESIDUAL / ANALYTICAL ADJUSTMENTS
B8: JPY Under-hedge Residual Exposure (USD) | C8: 2150000 | D8: Input (Decision D-07): loan notional reset Nov-2025; forward not updated. Source rank 2.
B9: Linked Haruki Loan Balance (USD) | C9: =SUMIF(Loan_Book!D6:D22,"Haruki Anime Studios KK",Loan_Book!H6:H22) -> 18000000 | D9: From Loan_Book obligor balance

Sheet Derivatives_IRS
B2: Item | C2: Value | D2: Source / Notes
B3: Notional Amount | C3: 250000000 | D3: IRS Confirmation
B4: Trade Date | C4: 45350 | D4: IRS Confirmation
B5: Effective Date | C5: 45355 | D5: IRS Confirmation
B6: Termination Date | C6: 46450 | D6: IRS Confirmation
B7: Fixed Rate paid by Fund | C7: 0.04425 | D7: IRS Confirmation
B8: Floating Rate received by Fund | C8: Originally 3M LIBOR, now Term SOFR + 26.161 bps | D8: ISDA Fallback + sticky note
B9: Facility Interest Rate (what Fund actually pays) | C9: Term SOFR + 11.448 bps + 2.75% | D9: Greystone Facility Agreement
B10: Basis Mismatch (Spread Difference) | C10: 14.713 | D10: bps | Source: 26.161 – 11.448 (ISDA Fallback vs Facility CSA)
B11: Mark-to-Market (31-Dec-2025) | C11: -3842000 | D11: Fund is out-of-the-money
B12: Hedge Design Intent | C12: Convert floating facility cost into synthetic fixed rate | D12: Deal memo in confirmation
B13: Hedge Accounting | C13: Not applied | D13: Explicitly stated
B14: Current Effectiveness | C14: Imperfect: persistent 14.713 bps basis risk remains | D14: Analysis
B15: Annual Cost of Basis Mismatch (approx) | C15: =C3*C10/10000 -> 367825 | D15: Formula: Notional × Basis bps / 10,000

Sheet Derivatives_MTM_Summary
B2: Asset_Class | C2: Trade_Ref | D2: Fair_Value_to_Fund_USD | E2: Status | F2: Notes
B3: Interest Rate Swap | C3: GTB-IRS-2024-0342 | D3: -3842000 | E3: Open | F3: Matches previous IRS sheet
B4: CDS - Orion | C4: ARI-WTM-CDS-0011 | D4: 0 | E4: Closed | F4: Settlement $14,437,500 direction assumed as receipt (protection buyer)
B5: CDS - Lumivue | C5: ARI-WTM-CDS-0018 | D5: 1245000 | E5: Open | F5: Protection buyer
B6: CDS - Timberline Ent | C6: ARI-WTM-CDS-0022 | D6: -720000 | E6: Open | F6: Protection seller (income trade)
B7: FX Forward EUR | C7: WTM-FX-0046 | D7: -92625 | E7: Open | F7: Unrealised loss
B8: Listed Options (Net) | C8: Various listed (ORNX, LMVU, EMBL, PRMK) | D8: 60500 | E8: Open | F8: Net mark-to-market of all listed options from Prime Broker report
B9: OTC Options (Net) | C9: FRGF-PUT-JUN26 + SLRA-CALL-JAN27 | D9: 52058 | E9: Open | F9: Frostgate converted from GBp to USD; Solara is model-based (Level 3)
B10: Total Derivatives MTM | C10: NA | D10: =SUM(D3:D9) -> -3297067 | E10: NA | F10: Sum of above
B11: Net Collateral Posted | C11: NA | D11: 6800000 | E11: NA | F11: Fund has posted more than received

Sheet Derivatives_Options
B2: Category | C2: Description | D2: Amount_USD | E2: Notes
B3: Open Positions - Net Mark-to-Market | C3: All open options combined | D3: 243000 | E3: After converting Frostgate to USD
B4: Realised P&L in Q4 | C4: Closed and expired options | D4: 10500 | E4: +66,000 –17,500 –38,000
B5: Short Option Liability | C5: Written calls and puts (Orion, Emberlight, Lumivue) | D5: -158500 | E5: Potential future obligation
B6: Frostgate OTC Put (corrected) | C6: Long put on Frostgate | D6: 65442 | E6: Converted from GBp at 1.2585
B7: Solara OTC Call | C7: Long call on private company | D7: 117500 | E7: Model-based valuation (Level 3)

Sheet Leased_Assets_Summary
B2: Lease_ID | C2: Asset_Category | D2: Description | E2: Payment_Frequency | F2: Payment_Amount_USD | G2: Annual_Cost_USD | H2: Treatment | I2: Notes
B3: LEASE-NYC-M | C3: Office | D3: NYC Headquarters | E3: Monthly | F3: 142000 | G3: 1704000 | H3: Operating Expense | I3: Fund HQ
B4: LEASE-LA-M | C4: Office | D4: LA Office | E4: Monthly | F4: 88000 | G4: 1056000 | H4: Operating Expense
B5: LEASE-CMP-M | C5: IT Infrastructure | D5: Managed Cloud (Northwind) | E5: Monthly | F5: 215000 | G5: 2580000 | H5: Operating Expense
B6: LEASE-CML-Q | C6: Content Library | D6: Longwood Music Catalog | E6: Quarterly | F6: 450000 | G6: 1800000 | H6: Investment Cost (Sleeve) | I6: Portfolio view chosen: cost to structured credit sleeve
B7: LEASE-CML-Q2 | C7: Content Library | D7: Greystone Bridge Film Library | E7: Quarterly | F7: 85000 | G7: 340000 | H7: Operating Expense | I7: Agreed opex treatment
B8: LEASE-JPY-Q | C8: Content Library | D8: Nishimura Anime Titles (JPY) | E8: Quarterly | F8: 207205 | G8: 828820 | H8: Operating Expense | I8: FX unhedged: amount at Q4 spot
B9: Total Annual Lease Cost | C9: All Categories | D9: All Leases | E9: Annual | F9: =G9 -> 8308820 | G9: =SUM(G3:G8) -> 8308820 | H9: Mixed | I9: Sum of all leases above
B10: Of which charged to Sleeve | C10: Content Library | D10: Longwood Music Catalog only | E10: Annual | F10: =F6*4 -> 1800000 | G10: =F10 -> 1800000 | H10: Investment Cost (Sleeve) | I10: Only Longwood under Portfolio view

Sheet Cash_Ledger_Summary
B2: Category | C2: Sub_Category | D2: Amount_USD | E2: Direction | F2: Linked_To | G2: Notes
B3: Loan Interest Received | C3: Performing Loans | D3: 4000000 | E3: Inflow | F3: Loan Book | G3: Sum of all cash coupons received in Q4 (excl. PIK & missed)
B4: Loan Interest Received | C4: Bridge Loan | D4: 127000 | E4: Inflow | F4: WTM-L-0012
B5: Loan Interest Not Received | C5: Orion Mezzanine | D5: 0 | E5: None | F5: WTM-L-0002 | G5: Missed Q4 coupon: $640,625 accrued but not paid
B6: Debt Cost | C6: Greystone Revolver Interest | D6: -5250000 | E6: Outflow | F6: Facility
B7: Debt Cost | C7: Greystone Commitment Fee | D7: -93750 | E7: Outflow | F7: Facility
B8: Debt Cost | C8: Ironbridge Term Loan Interest | D8: -8250000 | E8: Outflow | F8: Ironbridge
B9: Derivatives | C9: IRS Net Payments (Q3) | D9: -475000 | E9: Outflow | F9: IRS | G9: Net of the two conflicting entries (needs cleaning)
B10: Derivatives | C10: CDS Premiums (Net) | D10: -27500 | E10: Outflow | F10: CDS | G10: Premiums paid minus premiums received
B11: Derivatives | C11: Orion CDS Settlement | D11: 14437500 | E11: Inflow | F11: Orion CDS | G11: Major receipt – supports protection buyer assumption
B12: Derivatives | C12: FX Forward Rolls & Settlements | D12: -96000 | E12: Outflow | F12: FX Forwards | G12: Net cash on GBP roll
B13: Derivatives | C13: Options Premiums & Exercise | D13: -1262000 | E13: Outflow | F13: Options | G13: Premium received $88k minus exercise payment $1.35m
B14: Leases | C14: Content Library (Longwood) | D14: -450000 | E14: Outflow | F14: Leased Assets
B15: Leases | C15: Office (NYC + LA) | D15: -230000 | E15: Outflow | F15: Leased Assets
B16: Leases | C16: IT / Cloud (Northwind) | D16: -215000 | E16: Outflow | F16: Leased Assets
B17: LP Flows | C17: Capital Call Received | D17: 25000000 | E17: Inflow | F17: LPs
B18: LP Flows | C18: Distribution Paid | D18: -15000000 | E18: Outflow | F18: LPs
B19: LP Flows | C19: Capital Call Refund | D19: -3200000 | E19: Outflow | F19: LPs | G19: Over-call refund
B20: Fees & Admin | C20: Management Fee to GP | D20: -1900000 | E20: Outflow | F20: GP | G20: Q3 + Q4
B21: Fees & Admin | C21: Audit + Administrator | D21: -260000 | E21: Outflow | F21: Admin
B22: Other | C22: Bank Interest Income | D22: 45000 | E22: Inflow | F22: Cash
B23: Other | C23: Royalties Received | D23: 1195000 | E23: Inflow | F23: Content | G23: Streaming + Sync fees

Sheet Cash_vs_Recognised
B2: Metric | C2: Cash_Amount_USD | D2: Recognized_Amount_USD | E2: Gap_USD | F2: Explanation
B3: Loan Interest Income | C3: 4127000 | D3: 4908625 | E3: -781625 | F3: Cash coupons received vs Cash + PIK + missed Orion coupon
B4: Orion Mezzanine Write-down | C4: 0 | D4: -13125000 | E4: 13125000 | F4: Write-down is recognized but no cash moved
B5: Orion CDS Settlement | C5: 14437500 | D5: 14437500 | E5: 0 | F5: Both cash and recognized (we treated it as gain)
B6: IRS Fair Value Change | C6: -475000 | D6: -3842000 | E6: 3367000 | F6: Only net cash paid vs full MTM change
B7: FX Forwards Realised | C7: -96000 | D7: -2767460 | E7: 2671460 | F7: Only roll cash vs full realised losses we calculated earlier
B8: Options (Premiums + Exercise) | C8: -1262000 | D8: -1262000 | E8: 0 | F8: Mostly matched
B9: Leases Paid | C9: -895000 | D9: -895000 | E9: 0 | F9: Cash = expense
B10: Debt Interest Paid | C10: -13593750 | D10: -13593750 | E10: 0 | F10: Cash = expense
B11: Net Impact on Timing Gap | C11: 0 | D11: 0 | E11: {=SUM(ABS(E3:E10))} -> 19945085 | F11: Sum of absolute gaps (rough total recognition-timing difference)

Sheet Performance_Metrics
B2: Metric | C2: Value | D2: Unit | E2: Formula / Source | F2: Commentary
B3: Total Funded Balance | C3: =Loan_Book_Summary!D5 -> 456475000 | D3: USD | E3: Loan_Book_Summary | F3: Current outstanding loans after all adjustments
B4: Cash Interest Received (Q4) | C4: =Loan_Book_Summary!D7 -> 9967750 | D4: USD | E4: Loan_Book_Summary | F4: Actual cash coupons received
B5: Accrued PIK Interest (Q4) | C5: =Loan_Book_Summary!D9 -> 781250 | D5: USD | E5: Loan_Book_Summary | F5: Emberlight PIK – recognized but not cash
B6: Total Loan Income (Q4) | C6: =C5+C4 -> 10749000 | D6: USD | E6: Calculated | F6: Cash + PIK
B7: Cost of Debt (Q4) | C7: =Cash_Ledger_Summary!D6+Cash_Ledger_Summary!D7+Cash_Ledger_Summary!D8 -> -13593750 | D7: USD | E7: Cash_Ledger_Summary | F7: Greystone interest + commitment fee + Ironbridge interest
B8: Net Income before other items | C8: =C6+C7 -> -2844750 | D8: USD | E8: Calculated | F8: Loan income minus cost of debt
B9: Recognition Timing Gap (Absolute) | C9: =Cash_vs_Recognised!E11 -> 19945085 | D9: USD | E9: Cash_vs_Recognised | F9: Key risk metric: cash vs accounting difference
B10: Orion Mezzanine Write-down | C10: =Loan_Book_Summary!D16 -> 13125000 | D10: USD | E10: Loan_Book_Summary | F10: Loss on restructuring
B11: Orion CDS Settlement Gain | C11: =Derivatives_CDS!C10 -> 14437500 | D11: USD | E11: Derivatives_CDS | F11: Offsetting gain from protection
B12: Net Orion Impact | C12: =C11-C10 -> 1312500 | D12: USD | E12: Calculated | F12: CDS recovery minus write-down
B13: IRS Mark-to-Market | C13: =Derivatives_IRS!C11 -> -3842000 | D13: USD | E13: Derivatives_IRS | F13: Current fair value of the hedge
B14: IRS Basis Mismatch (Annual Cost) | C14: =Derivatives_IRS!C15 -> 367825 | D14: USD | E14: Derivatives_IRS | F14: Ongoing cost of imperfect hedge
B15: Hedge Effectiveness Assessment | C15: Imperfect | D15: Text | E15: Derivatives_IRS | F15: 14.713 bps permanent basis risk remains
B16: Longwood Lease Cost charged to Sleeve (Annual) | C16: =Leased_Assets_Summary!G6 -> 1800000 | D16: USD | E16: Leased_Assets_Summary | F16: Portfolio view treatment
B18: Net Yield before Leverage (Q4 annualised) | C18: =(C6/C3)*4 -> 0.094191358 | E18: (Total Loan Income / Funded Balance) × 4
B19: Net Yield after Debt Cost (Q4 annualised) | C19: =(C8/C3)*4 -> -0.024927981 | E19: (Net Income before other items / Funded Balance) × 4
B20: Recognition Timing Gap as % of Funded Balance | C20: =C9/C3 -> 0.043693707 | E20: Timing gap relative to book size
B23: Cash Conversion Ratio (Q4) | C23: =C4/C6 -> 0.92731882 | D23: Ratio | E23: Cash Interest / Total Loan Income | F23: Share of recognised loan income that is cash this quarter; complement of PIK drag
B24: PIK Share of Loan Income (Q4) | C24: =C5/C6 -> 0.07268118 | D24: Ratio | E24: Accrued PIK / Total Loan Income | F24: ~7% of Q4 income is non-cash (Emberlight PIK election)
B25: IRS Basis Drag: Annual ($) | C25: =Derivatives_IRS!C15 -> 367825 | D25: USD | E25: Derivatives_IRS annual basis cost | F25: Permanent 14.713 bps mismatch × IRS notional
B26: IRS Basis Drag: bps of Funded Book | C26: =C25/C3*10000 -> 8.057944 | D26: bps | E26: Annual basis $ / Funded Balance × 10,000 | F26: Basis leakage expressed relative to book size
B27: IRS Basis Drag: Days of Q4 Loan Income | C27: =C25/(C6/90) -> 3.0797516 | D27: Days | E27: Annual basis $ / (Q4 loan income per day) | F27: How many days of Q4 loan income the annual basis drag consumes
B28: JPY Residual FX Exposure ($) | C28: =Derivatives_FX_Forwards!C8 -> 2150000 | D28: USD | E28: Derivatives_FX_Forwards residual input | F28: Under-hedged residual after Nov-2025 notional reset (Decision D-07)
B29: JPY Residual: bps of Funded Book | C29: =C28/C3*10000 -> 47.10006 | D29: bps | E29: JPY residual $ / Funded Balance × 10,000 | F29: Residual FX exposure relative to book
B30: Combined Hedge Residual Cost (Annual $ proxy) | C30: =C25+C28 -> 2517825 | D30: USD | E30: IRS annual basis + JPY residual (stock) | F30: Note: mixes flow (annual basis) and stock (FX residual); useful as residual-risk headline
B31: Combined Residual: bps of Funded Book | C31: =C30/C3*10000 -> 55.158004 | D31: bps | E31: Combined residual $ / Funded × 10,000 | F31: Headline residual-risk intensity
B32: Break-even Asset Yield (ann.) for Zero Levered Return | C32: =ABS(C7)/C3*4 -> 0.11911934 | D32: Yield | E32: |Cost of Debt| / Funded × 4 | F32: Asset yield needed so loan income exactly covers debt cost (levered return = 0)
B33: Yield Gap vs Break-even (ann.) [- = shortfall] | C33: =C18-C32 -> -0.024927981 | D33: Yield pts | E33: Pre-leverage yield − break-even yield | F33: Pre-lev yield: break-even yield. Negative means asset book currently earns less than the annualised yield needed to cover debt cost (explains negative levered return).
B34: Leverage Drag (ann.) | C34: =C18-C19 -> 0.11911934 | D34: Yield pts | E34: Pre-lev yield - Post-lev yield | F34: How much leverage currently costs in yield terms
B35: Quarterly Income Shortfall vs Debt Cost ($) | C35: =C6-ABS(C7) -> -2844750 | D35: USD | E35: Q4 Loan Income - |Cost of Debt| | F35: Cash+PIK income does not cover debt cost this quarter by this amount

Sheet Decision_Quality
B2: Decision Quality & Assumption Log: Whitmore Fund II
B4: Total Material Decisions Made: 8
B5: High Confidence (8–10): 6
B6: Medium Confidence (5–7): 2
B7: Open Items Requiring Action: 2
B9: Decision_ID | C9: Decision_Area | D9: Decision_Made | E9: Alternative_Considered | F9: Rationale | G9: Confidence_Level | H9: Confidence_Score | I9: Potential_Impact_if_Wrong | J9: Impact_Amount_USD | K9: Status
B10: D-01 | C10: Orion CDS Direction | D10: Fund is Protection Buyer (receives settlement) | E10: Fund is Protection Seller (pays settlement) | F10: Primary Confirmation language takes priority over ops notes and reciprocal confirm as per case guidance | G10: High | H10: 9 | I10: Reverses the $14.44m gain into a loss | J10: 14437500 | K10: Closed
B11: D-02 | C11: Orion Mezzanine Valuation | D11: Carried at 47.5% of face ($11.875m) | E11: Use Auction Final Price 42.25% or keep at Par | F11: Follows the Restructuring Support Agreement terms; consistent with CDS recovery logic | G11: High | H11: 9 | I11: Changes write-down by $1.3m–$13.1m | J11: 1312500 to 13125000 | K11: Closed
B12: D-03 | C12: Longwood Content Library Lease | D12: Treated as Investment Cost to the Sleeve | E12: Treated as Operating Expense (Fund Accounting view) | F12: Consistent with LAIM capital-light strategy and Portfolio Manager view; royalties sit in entertainment sleeve | G12: Medium-High | H12: 7 | I12: Changes sleeve cost by $1.8m per year and affects Net Yield | J12: 1800000 | K12: Closed
B13: D-04 | C13: Interest Rate Swap Effectiveness | D13: Partially Effective (Imperfect) | E13: Fully Effective | F13: Permanent 14.713 bps basis mismatch remains after LIBOR transition | G13: High | H13: 9 | I13: Ongoing annual cost of ~$368k continues | J13: 367825 | K13: Open - Monitoring
B14: D-05 | C14: Emberlight PIK Treatment | D14: Recognized as Accrued Income + added to Principal | E14: Ignore or treat as contingent | F14: Loan agreement allows PIK; Notice confirms election; accrual accounting requires recognition | G14: High | H14: 8 | I14: Understates income and principal by $1.85m | J14: 1850000 | K14: Closed
B15: D-06 | C15: Timberline Prepayment | D15: Balance reduced to $30.5m | E15: Keep Alpha tape balance of $35m | F15: Corporate Action Notice 3 explicitly corrects the tape | G15: High | H15: 10 | I15: Overstates funded balance by $4.5m | J15: 4500000 | K15: Closed
B16: D-07 | C16: JPY Forward Notional | D16: Flagged as Under-hedged (no adjustment to loan balance) | E16: Force-update forward notional or adjust loan USD balance | F16: Loan agreement reset is real; forward was not updated; we disclose the residual risk | G16: Medium | H16: 6 | I16: Residual FX exposure of ~$2.15m remains | J16: 2150000 | K16: Open - Action Required
B17: D-08 | C17: Duplicate Loan Handling | D17: Single count only (Alpha preferred post-transfer) | E17: Double count or keep both | F17: Case explicitly warns against double counting; transfer dates respected | G17: High | H17: 10 | I17: Would inflate book by tens of millions | J17: Various | K17: Closed

Sheet Sensitivity_Analysis
B2: SENSITIVITY & SCENARIO ANALYSIS – Whitmore Fund II
B5: BASE CASE INPUTS (change these to run scenarios)
B6: Parameter | C6: Value | D6: Unit | E6: Notes / Driver
B7: Funded_Balance | C7: =Loan_Book_Summary!D5 -> 456475000 | D7: USD | E7: Linked → Loan_Book_Summary Total Funded Balance
B8: Loan_Income_Q4 | C8: =Performance_Metrics!C6 -> 10749000 | E8: Linked → Performance_Metrics Total Loan Income (Q4)
B9: Cost_of_Debt_Q4 | C9: =ABS(Performance_Metrics!C7) -> 13593750 | D9: USD | E9: Linked → |Performance_Metrics Cost of Debt (Q4)|
B10: Floating_Share_of_Book | C10: 0.65 | D10: % | E10: Approx % of loans that are floating
B11: Facility_Sensitivity | C11: 1 | D11: x | E11: How much facility cost moves with SOFR (1.0 = full)
B12: PIK_Shock_Amount | C12: 1200000 | D12: USD | E12: Assumed extra income that becomes PIK
B13: Utilization_Uplift_Cost | C13: 606250 | D13: USD | E13: Extra interest if utilization rises to ~80%
B16: SCENARIO RESULTS (driven by inputs above)
B17: Scenario | C17: Loan Income | D17: Cost of Debt | E17: Net Income | F17: Net Yield after Debt (ann.) | G17: Change vs Base | H17: Key Assumption
B18: Base Case | C18: =C8 -> 10749000 | D18: =C9 -> 13593750 | E18: =C18-D18 -> -2844750 | F18: =E18/C7*4 -> -0.024927981 | G18: 0 | H18: Current position
B19: SOFR +100 bps | C19: =C8+(C8*C10*0.01) -> 10818868 | D19: =C9+(C9*C11*0.01) -> 13729688 | E19: =C19-D19 -> -2910819 | F19: =E19/C7*4 -> -0.02550693 | G19: =F19-F18 -> -0.00057894956 | H19: Floating loans + facility cost both rise 100 bps
B20: SOFR -50 bps | C20: =C8-(C8*C10*0.005) -> 10714066 | D20: =C9-(C9*C11*0.005) -> 13525781 | E20: =C20-D20 -> -2811715.5 | F20: =E20/C7*4 -> -0.024638506 | G20: =F20-F18 -> 0.00028947478 | H20: Floating rates fall 50 bps
B21: 2 Additional Loans go PIK | C21: =C8-C12 -> 9549000 | D21: =C9 -> 13593750 | E21: =C21-D21 -> -4044750 | F21: =E21/C7*4 -> -0.035443343 | G21: =F21-F18 -> -0.010515362 | H21: Extra $1.2m of income converts from cash to PIK
B22: Greystone Utilization → 80% | C22: =C8 -> 10749000 | D22: =C9+C13 -> 14200000 | E22: =C22-D22 -> -3451000 | F22: =E22/C7*4 -> -0.030240429 | G22: =F22-F18 -> -0.0053124487 | H22: Higher drawn balance increases interest cost
B23: Break-even Yield Required | C23: =C9 -> 13593750 | D23: =C9 -> 13593750 | E23: =C23-D23 -> 0 | F23: 0 | G23: =F23-F18 -> 0.024927981 | H23: Break-even: loan income set = cost of debt → post-lev yield = 0. Required asset yield = Performance_Metrics!C32
B24: Longwood Lease moved to Opex | C24: =C8 -> 10749000 | D24: =C9 -> 13593750 | E24: =C24-D24 -> -2844750 | F24: =E24/C7*4 -> -0.024927981 | G24: =F24-F18 -> 0 | H24: Only allocation changes – income & debt cost unchanged
B26: KEY INSIGHTS
B27: 1. Asset-side yield (9.42%) is healthy; the problem is the current cost of leverage.
B28: 2. The sleeve remains negatively geared after debt cost in most realistic scenarios.
B29: 3. Largest downside risks: rising SOFR and more loans electing PIK. | F29: s
B30: 4. Break-even analysis shows the loan book still has a good cushion before it fails to cover debt cost.
B31: 5. Yellow cells above are the drivers – change them and all scenario results update automatically.
B33: HOW TO USE WITH EXCEL SCENARIO MANAGER
B34: 1. Select the yellow input cells (B6:B12)
B35: 2. Data → What-If Analysis → Scenario Manager → Add
B36: 3. Create named scenarios (Base, SOFR+100, PIK Shock, etc.) by changing the yellow cells
B37: 4. The results table (rows 17-23) will recalculate for each scenario
B39: BREAK-EVEN YIELD GAUGE (linked to Performance_Metrics)
B40: Current Pre-Leverage Yield (ann.) | C40: =Performance_Metrics!C18 -> 0.094191358
B41: Break-even Asset Yield (ann.) | C41: =Performance_Metrics!C32 -> 0.11911934
B42: Cushion (Pre-Lev − Break-even) | C42: =Performance_Metrics!C33 -> -0.024927981
B43: Current Post-Leverage Yield (ann.) | C43: =Performance_Metrics!C19 -> -0.024927981
B44: Interpretation | C44: Positive cushion means asset book still earns above the yield needed to cover debt cost. Negative post-lev yield means leverage is currently expensive relative to asset income this quarter.

Sheet Stakeholder_Views
B2: Stakeholder Views & Information Needs Whitmore Structured Credit Opportunities Fund II As of 31 December 2025
B5: 1. Portfolio Manager View
B7: Metric | C7: Value | D7: Comment
B8: Net Yield before Leverage | C8: 0.0942 | D8: Healthy asset-level return
B9: Net Yield after Debt Cost | C9: -0.0249 | D9: Currently negative after leverage
B10: Total Loan Income (Q4) | C10: 10750000 | D10: Cash + PIK
B11: Net Orion Impact | C11: 1310000 | D11: CDS recovery exceeded write-down
B12: IRS Hedge Status | C12: Imperfect | D12: 14.7 bps ongoing basis cost
B15: 2. Fund Accounting / Finance View
B17: Metric | C17: Value | D17: Comment
B18: Recognition Timing Gap | C18: 19950000 | D18: Material difference
B19: Timing Gap as % of Book | C19: 0.0437 | D19: Elevated
B20: PIK Interest (Q4) | C20: 780000 | D20: Recognized but non-cash
B21: Orion Write-down | C21: 13130000 | D21: Fully recognized
B22: Longwood Lease Treatment | C22: Investment Cost (Sleeve) | D22: Portfolio view applied
B25: 3. Risk Manager View
B27: Metric | C27: Value | D27: Comment
B28: Largest Counterparty | C28: Greystone | D28: Facility + IRS
B29: IRS Hedge Effectiveness | C29: Partially Effective | D29: Permanent basis mismatch
B30: Annual Basis Cost | C30: 368000 | D30: Ongoing leakage
B31: JPY Under-hedge | C31: 2150000 | D31: Action required
B32: Recognition Timing Gap | C32: 19950000 | D32: Key risk metric
B35: 4. Investment Operations View
B37: Item | C37: Number | D37: Comment
B38: Material Decisions Made | C38: 8 | D38: Fully documented
B39: High Confidence Decisions | C39: 6 | D39: Strong audit trail
B40: Open Action Items | C40: 2 | D40: JPY hedge + IRS basis
B41: Major Overrides Applied | C41: 4 | D41: Timberline, Orion Mezz, PIK, CDS direction
B42: Source Hierarchy Used | C42: Formal docs > Notices > Tapes > Notes | D42: Case rule followed
B45: 5. Investment Committee / Senior Management View
B47: Area | C47: Status | D47: One-line Summary
B48: Asset Yield | C48: Strong | D48: 9.42% before leverage
B49: Levered Performance | C49: Weak | D49: -2.49% after debt cost
B50: Hedge Quality | C50: Partial | D50: Basis leakage continues
B51: Concentration | C51: Elevated | D51: Heavy Greystone exposure
B52: Accounting Quality | C52: Acceptable | D52: Large but explained timing gap
B53: Overall Assessment | C53: Mixed | D53: Good assets, expensive leverage, residual risks
B56: 6. LP / Investor View
B58: Metric | C58: Value | D58: Comment
B59: Net Yield after Debt | C59: -0.0249 | D59: Current levered return
...

Sheet Concentration_Analysis
B2: CONCENTRATION ANALYSIS – Single-Name & Counterparty Dual View
B4: Obligor | C4: Funded Balance (USD) | D4: % of Book | E4: Rank | F4: Notes
B5: Orion Studios Holdings LLC | C5: =SUMIF(Loan_Book!D$6:D$22,B5,Loan_Book!H$6:H$22) -> 66625000 | D5: =IF(Loan_Book_Summary!$D$5=0,0,C5/Loan_Book_Summary!$D$5) -> 0.14595542 | E5: =RANK(C5,$C$5:$C$17,0) -> 2 | F5: Term A + Mezz + Revolver; restructured mezz
B6: Emberlight Records Group | C6: =SUMIF(Loan_Book!D$6:D$22,B6,Loan_Book!H$6:H$22) -> 60350000 | D6: =IF(Loan_Book_Summary!$D$5=0,0,C6/Loan_Book_Summary!$D$5) -> 0.13220877 | E6: =RANK(C6,$C$5:$C$17,0) -> 3 | F6: Senior + PIK toggle
B7: Lumivue Streaming Corp | C7: =SUMIF(Loan_Book!D$6:D$22,B7,Loan_Book!H$6:H$22) -> 120000000 | D7: =IF(Loan_Book_Summary!$D$5=0,0,C7/Loan_Book_Summary!$D$5) -> 0.26288406 | E7: =RANK(C7,$C$5:$C$17,0) -> 1 | F7: Unitranche + Second Lien
B8: Timberline Music Rights I LLC | C8: =SUMIF(Loan_Book!D$6:D$22,B8,Loan_Book!H$6:H$22) -> 30500000 | D8: =IF(Loan_Book_Summary!$D$5=0,0,C8/Loan_Book_Summary!$D$5) -> 0.066816365 | E8: =RANK(C8,$C$5:$C$17,0) -> 5 | F8: Prepayment-adjusted balance
B9: Solara Content Partners | C9: =SUMIF(Loan_Book!D$6:D$22,B9,Loan_Book!H$6:H$22) -> 32000000 | D9: =IF(Loan_Book_Summary!$D$5=0,0,C9/Loan_Book_Summary!$D$5) -> 0.070102415 | E9: =RANK(C9,$C$5:$C$17,0) -> 4 | F9: Revolver drawn
B10: Thornbury Publishing GBP LTD | C10: =SUMIF(Loan_Book!D$6:D$22,B10,Loan_Book!H$6:H$22) -> 28000000 | D10: =IF(Loan_Book_Summary!$D$5=0,0,C10/Loan_Book_Summary!$D$5) -> 0.061339613 | E10: =RANK(C10,$C$5:$C$17,0) -> 6 | F10: GBP loan; FX-hedged
B11: Frostgate Films Ltd | C11: =SUMIF(Loan_Book!D$6:D$22,B11,Loan_Book!H$6:H$22) -> 22000000 | D11: =IF(Loan_Book_Summary!$D$5=0,0,C11/Loan_Book_Summary!$D$5) -> 0.04819541 | E11: =RANK(C11,$C$5:$C$17,0) -> 7 | F11: Floating film production
B12: Haruki Anime Studios KK | C12: =SUMIF(Loan_Book!D$6:D$22,B12,Loan_Book!H$6:H$22) -> 18000000 | D12: =IF(Loan_Book_Summary!$D$5=0,0,C12/Loan_Book_Summary!$D$5) -> 0.039432609 | E12: =RANK(C12,$C$5:$C$17,0) -> 9 | F12: JPY revenue; FX under-hedged
B13: Prismrock Live Events Inc | C13: =SUMIF(Loan_Book!D$6:D$22,B13,Loan_Book!H$6:H$22) -> 20000000 | D13: =IF(Loan_Book_Summary!$D$5=0,0,C13/Loan_Book_Summary!$D$5) -> 0.04381401 | E13: =RANK(C13,$C$5:$C$17,0) -> 8 | F13: Live entertainment
B14: Equinox Live Ent GmbH | C14: =SUMIF(Loan_Book!D$6:D$22,B14,Loan_Book!H$6:H$22) -> 18000000 | D14: =IF(Loan_Book_Summary!$D$5=0,0,C14/Loan_Book_Summary!$D$5) -> 0.039432609 | E14: =RANK(C14,$C$5:$C$17,0) -> 9 | F14: EUR loan
B15: Ridgeline Post-Production LLC | C15: =SUMIF(Loan_Book!D$6:D$22,B15,Loan_Book!H$6:H$22) -> 15000000 | D15: =IF(Loan_Book_Summary!$D$5=0,0,C15/Loan_Book_Summary!$D$5) -> 0.032860507 | E15: =RANK(C15,$C$5:$C$17,0) -> 11 | F15: Post production
B16: Dawnridge Post-Prod Services | C16: =SUMIF(Loan_Book!D$6:D$22,B16,Loan_Book!H$6:H$22) -> 14000000 | D16: =IF(Loan_Book_Summary!$D$5=0,0,C16/Loan_Book_Summary!$D$5) -> 0.030669807 | E16: =RANK(C16,$C$5:$C$17,0) -> 12 | F16: Transferred Beta→Alpha
B17: Greystone Bridge Loan | C17: =SUMIF(Loan_Book!D$6:D$22,B17,Loan_Book!H$6:H$22) -> 12000000 | D17: =IF(Loan_Book_Summary!$D$5=0,0,C17/Loan_Book_Summary!$D$5) -> 0.026288406 | E17: =RANK(C17,$C$5:$C$17,0) -> 13 | F17: Short-dated bridge (also facility relationship)
B18: TOTAL (check vs Funded Balance) | C18: =SUM(C5:C17) -> 456475000 | D18: =SUM(D5:D17) -> 1
B20: Concentration Metrics (formula)
B21: Largest Single Obligor Balance | C21: =MAX(C5:C17) -> 120000000
B22: Largest Single Obligor % of Book | C22: =MAX(D5:D17) -> 0.26288406
B23: Top-3 Obligors % of Book | C23: =(LARGE(D5:D17,1)+LARGE(D5:D17,2)+LARGE(D5:D17,3)) -> 0.54104825
B25: B. COUNTERPARTY DUAL-CHANNEL VIEW (Greystone)
B26: Channel | C26: Amount (USD) | D26: % / Context | E26: Source
B27: 1. Lending (Bridge loan to Greystone-related) | C27: =SUMIF(Loan_Book!D6:D22,"Greystone Bridge Loan",Loan_Book!H6:H22) -> 12000000 | D27: =C27/Loan_Book_Summary!$D$5 -> 0.026288406 | E27: Loan_Book obligor balance
B28: 2. Financing – IRS Notional (Greystone) | C28: =Derivatives_IRS!C3 -> 250000000 | D28: Hedge notional (not funded asset) | E28: Derivatives_IRS confirmation
B29: 3. Financing – Q4 Greystone Facility Interest Paid | C29: =ABS(Cash_Ledger_Summary!D6) -> 5250000 | D29: Q4 interest outflow | E29: Cash_Ledger_Summary
B30: 4. Financing – Q4 Greystone Commitment Fee | C30: =ABS(Cash_Ledger_Summary!D7) -> 93750 | D30: Q4 commitment fee | E30: Cash_Ledger_Summary
B31: Combined Greystone Economic Touchpoints (headline) | C31: =C27+C28 -> 262000000 | D31: Asset balance + IRS notional (dual channel) | E31: Illustrates single-name dependency across lending & hedging
B33: Insight: Greystone is both a loan obligor (bridge) and the dominant financing/hedge counterparty (facility interest + $250m IRS). Concentration risk is multi-channel, not just single-name asset risk.

Sheet Recommendations
B2: RECOMMENDATIONS: Whitmore Fund II Structured Credit Sleeve
B3: As of 31 December 2025
B5: Priority ranking: 1 = Highest urgency / impact
B9: 1. Restrike or Unwind the Interest Rate Swap
B10: Priority: High
B11: Owner: Trading Desk / Portfolio Management
B12: Impact: Stops ongoing ~$368k annual basis leakage
B13: Rationale: Permanent 14.713 bps mismatch remains after LIBOR → SOFR transition. The hedge is only partially effective. Continuing to hold it creates a structural drag on levered returns.
B14: Suggested Action: Obtain fresh quotes to restrike the floating leg to match the actual facility CSA (or unwind and reassess hedge need).
B18: 2. Update JPY Forward Notional Immediately
B19: Priority: High
B20: Owner: Middle Office / FX Desk
... B50: Suggested Action: Produce a short Cash-to-Accrual bridge as part of the regular reporting pack.
